go go, powerrangers!
terminate called after throwing an instance of 'std::bad_alloc'
terminate called after throwing an instance of '  what():  std::bad_allocstd::bad_alloc'

  what():  std::bad_allocterminate called after throwing an instance of '
std::bad_alloc'
2013-06-29 14:27:31.558 (WARN ) [0x40000fd8c80] :498887:ibm.runjob.client.Job: terminated by signal 6
2013-06-29 14:27:31.559 (WARN ) [0x40000fd8c80] :498887:ibm.runjob.client.Job: abnormal termination by signal 6 from rank 4429
done
